2023-12-17 17:10:35,838 (__init__.py:960 MainThread) ERROR - TeleBot: "Infinity polling exception: "
2023-12-17 17:10:35,839 (__init__.py:962 MainThread) ERROR - TeleBot: "Exception traceback:
Traceback (most recent call last):
  File "/Users/goods/Desktop/code_/currency/venv/lib/python3.10/site-packages/gspread/client.py", line 150, in open
    properties = finditem(
  File "/Users/goods/Desktop/code_/currency/venv/lib/python3.10/site-packages/gspread/utils.py", line 133, in finditem
    return next(item for item in seq if func(item))
StopIteration

During handling of the above exception, another exception occurred:

Traceback (most recent call last):
  File "/Users/goods/Desktop/code_/currency/venv/lib/python3.10/site-packages/telebot/__init__.py", line 955, in infinity_polling
    self.polling(non_stop=True, timeout=timeout, long_polling_timeout=long_polling_timeout,
  File "/Users/goods/Desktop/code_/currency/venv/lib/python3.10/site-packages/telebot/__init__.py", line 1043, in polling
    self.__threaded_polling(non_stop=non_stop, interval=interval, timeout=timeout, long_polling_timeout=long_polling_timeout,
  File "/Users/goods/Desktop/code_/currency/venv/lib/python3.10/site-packages/telebot/__init__.py", line 1118, in __threaded_polling
    raise e
  File "/Users/goods/Desktop/code_/currency/venv/lib/python3.10/site-packages/telebot/__init__.py", line 1074, in __threaded_polling
    self.worker_pool.raise_exceptions()
  File "/Users/goods/Desktop/code_/currency/venv/lib/python3.10/site-packages/telebot/util.py", line 147, in raise_exceptions
    raise self.exception_info
  File "/Users/goods/Desktop/code_/currency/venv/lib/python3.10/site-packages/telebot/util.py", line 90, in run
    task(*args, **kwargs)
  File "/Users/goods/Desktop/code_/currency/venv/lib/python3.10/site-packages/telebot/__init__.py", line 6788, in _run_middlewares_and_handler
    result = handler['function'](message)
  File "/Users/goods/Desktop/code_/currency/telegrambro.py", line 24, in ratesBot
    main()
  File "/Users/goods/Desktop/code_/currency/update_currency/sxrt.py", line 29, in main
    sh = sa.open("Деньги")
  File "/Users/goods/Desktop/code_/currency/venv/lib/python3.10/site-packages/gspread/client.py", line 160, in open
    raise SpreadsheetNotFound
gspread.exceptions.SpreadsheetNotFound
"
2023-12-17 17:30:58,522 (__init__.py:960 MainThread) ERROR - TeleBot: "Infinity polling exception: HTTPSConnectionPool(host='api.telegram.org', port=443): Read timed out. (read timeout=25)"
2023-12-17 17:30:58,525 (__init__.py:962 MainThread) ERROR - TeleBot: "Exception traceback:
Traceback (most recent call last):
  File "/Users/goods/Desktop/code_/currency/venv/lib/python3.10/site-packages/urllib3/connectionpool.py", line 466, in _make_request
    six.raise_from(e, None)
  File "<string>", line 3, in raise_from
  File "/Users/goods/Desktop/code_/currency/venv/lib/python3.10/site-packages/urllib3/connectionpool.py", line 461, in _make_request
    httplib_response = conn.getresponse()
  File "/Library/Frameworks/Python.framework/Versions/3.10/lib/python3.10/http/client.py", line 1374, in getresponse
    response.begin()
  File "/Library/Frameworks/Python.framework/Versions/3.10/lib/python3.10/http/client.py", line 318, in begin
    version, status, reason = self._read_status()
  File "/Library/Frameworks/Python.framework/Versions/3.10/lib/python3.10/http/client.py", line 279, in _read_status
    line = str(self.fp.readline(_MAXLINE + 1), "iso-8859-1")
  File "/Library/Frameworks/Python.framework/Versions/3.10/lib/python3.10/socket.py", line 705, in readinto
    return self._sock.recv_into(b)
  File "/Library/Frameworks/Python.framework/Versions/3.10/lib/python3.10/ssl.py", line 1274, in recv_into
    return self.read(nbytes, buffer)
  File "/Library/Frameworks/Python.framework/Versions/3.10/lib/python3.10/ssl.py", line 1130, in read
    return self._sslobj.read(len, buffer)
TimeoutError: The read operation timed out

During handling of the above exception, another exception occurred:

Traceback (most recent call last):
  File "/Users/goods/Desktop/code_/currency/venv/lib/python3.10/site-packages/requests/adapters.py", line 486, in send
    resp = conn.urlopen(
  File "/Users/goods/Desktop/code_/currency/venv/lib/python3.10/site-packages/urllib3/connectionpool.py", line 798, in urlopen
    retries = retries.increment(
  File "/Users/goods/Desktop/code_/currency/venv/lib/python3.10/site-packages/urllib3/util/retry.py", line 550, in increment
    raise six.reraise(type(error), error, _stacktrace)
  File "/Users/goods/Desktop/code_/currency/venv/lib/python3.10/site-packages/urllib3/packages/six.py", line 770, in reraise
    raise value
  File "/Users/goods/Desktop/code_/currency/venv/lib/python3.10/site-packages/urllib3/connectionpool.py", line 714, in urlopen
    httplib_response = self._make_request(
  File "/Users/goods/Desktop/code_/currency/venv/lib/python3.10/site-packages/urllib3/connectionpool.py", line 468, in _make_request
    self._raise_timeout(err=e, url=url, timeout_value=read_timeout)
  File "/Users/goods/Desktop/code_/currency/venv/lib/python3.10/site-packages/urllib3/connectionpool.py", line 357, in _raise_timeout
    raise ReadTimeoutError(
urllib3.exceptions.ReadTimeoutError: HTTPSConnectionPool(host='api.telegram.org', port=443): Read timed out. (read timeout=25)

During handling of the above exception, another exception occurred:

Traceback (most recent call last):
  File "/Users/goods/Desktop/code_/currency/venv/lib/python3.10/site-packages/telebot/__init__.py", line 955, in infinity_polling
    self.polling(non_stop=True, timeout=timeout, long_polling_timeout=long_polling_timeout,
  File "/Users/goods/Desktop/code_/currency/venv/lib/python3.10/site-packages/telebot/__init__.py", line 1043, in polling
    self.__threaded_polling(non_stop=non_stop, interval=interval, timeout=timeout, long_polling_timeout=long_polling_timeout,
  File "/Users/goods/Desktop/code_/currency/venv/lib/python3.10/site-packages/telebot/__init__.py", line 1118, in __threaded_polling
    raise e
  File "/Users/goods/Desktop/code_/currency/venv/lib/python3.10/site-packages/telebot/__init__.py", line 1073, in __threaded_polling
    polling_thread.raise_exceptions()
  File "/Users/goods/Desktop/code_/currency/venv/lib/python3.10/site-packages/telebot/util.py", line 108, in raise_exceptions
    raise self.exception_info
  File "/Users/goods/Desktop/code_/currency/venv/lib/python3.10/site-packages/telebot/util.py", line 90, in run
    task(*args, **kwargs)
  File "/Users/goods/Desktop/code_/currency/venv/lib/python3.10/site-packages/telebot/__init__.py", line 649, in __retrieve_updates
    updates = self.get_updates(offset=(self.last_update_id + 1),
  File "/Users/goods/Desktop/code_/currency/venv/lib/python3.10/site-packages/telebot/__init__.py", line 623, in get_updates
    json_updates = apihelper.get_updates(self.token, offset, limit, timeout, allowed_updates, long_polling_timeout)
  File "/Users/goods/Desktop/code_/currency/venv/lib/python3.10/site-packages/telebot/apihelper.py", line 321, in get_updates
    return _make_request(token, method_url, params=payload)
  File "/Users/goods/Desktop/code_/currency/venv/lib/python3.10/site-packages/telebot/apihelper.py", line 156, in _make_request
    result = _get_req_session().request(
  File "/Users/goods/Desktop/code_/currency/venv/lib/python3.10/site-packages/requests/sessions.py", line 589, in request
    resp = self.send(prep, **send_kwargs)
  File "/Users/goods/Desktop/code_/currency/venv/lib/python3.10/site-packages/requests/sessions.py", line 703, in send
    r = adapter.send(request, **kwargs)
  File "/Users/goods/Desktop/code_/currency/venv/lib/python3.10/site-packages/requests/adapters.py", line 532, in send
    raise ReadTimeout(e, request=request)
requests.exceptions.ReadTimeout: HTTPSConnectionPool(host='api.telegram.org', port=443): Read timed out. (read timeout=25)
"
